Workbook

Sheet Guidance
B8: Implementation Guidance This Excel sheet must be removed from the final version of the document.
B10: Design This spreadsheet has been designed using CertiKit's colour scheme. To choose a different colour scheme, go to the Page Layout ribbon, select Themes and choose a different style.
B12: Purpose of this document This document should be used to assess the level of conformity of an organization against the ISO22301 standard. It may be used by a consultant on behalf of a client or by an organization directly.
B14: Areas of the standard addressed All areas of the ISO22301 standard are covered.
B16: General guidance This tool allows you to perform a gap assessment against the ISO22301 standard. The questions asked are based on the contents of the relevant standard and are designed to give a reasonable assessment of the degree to which the relevant requirements are met. In all cases a "Yes" answer is taken as a positive indication. The results are summarised in a series of tables and in a selection of charts. If you would prefer to assess your conformity directly against the requirements of the standard, CertiKit provides a separate chargeable product, the CertiKit Enhanced Gap Assessment Tool, which lists the exact requirements from the standard, line by line. Because this second option contains the full text from the standard, it is subject to a licensing agreement that CertiKit maintains with the ISO via BSI. The Enhanced Gap Assessment Tool is available for purchase from our website.
B18: Review frequency It is a good idea to revisit this assessment on a regular basis throughout your project to obtain an indication of progress and as a final check prior to an external audit.
B20: Toolkit version number ISO22301 Toolkit Version 6
B22: Copyright notice Except for any specifically identified third-party works included, this document has been authored by CertiKit, and is ©CertiKit except as stated below. CertiKit is a company registered in England and Wales with company number 6432088.
B24: Licence terms This document is licensed on and subject to the standard licence terms of CertiKit, available on request, or by download from our website. All other rights are reserved. Unless you have purchased this product you only have an evaluation licence. If this product was purchased, a full licence is granted to the person identified as the licensee in the relevant purchase order. The standard licence terms include special terms relating to any third party copyright included in this document.
B26: Disclaimer Please Note: Your use of and reliance on this document template is at your sole risk. Document templates are intended to be used as a starting point only from which you will create your own document and to which you will apply all reasonable quality checks before use. Therefore please note that it is your responsibility to ensure that the content of any document you create that is based on our templates is correct and appropriate for your needs and complies with relevant laws in your country. You should take all reasonable and proper legal and other professional advice before using this document. CertiKit makes no claims, promises, or guarantees about the accuracy, completeness, or adequacy of our document templates, assumes no duty of care to any person with respect its document templates or their contents, and expressly excludes and disclaims liability for any cost, expense, loss or damage suffered or incurred in reliance on our document templates, or in expectation of our document templates meeting your needs, including (without limitation) as a result of misstatements, errors and omissions in their contents.

Sheet Assessment Details
B8: Assessment Details
B10: Date(s) of assessment
B11: Standard addressed:
B12: Location of assessment
B13: Assessor
B14: Assessment participants
B15: Purpose of assessment
B16: Scope of assessment

Sheet ISO22301 Gap Assessment
E6: Terms used
E7: BCMS = Business Continuity Management System
B9: AREA/SECTION | C9: SUB-SECTION | D9: ISO22301 REQUIREMENTS | E9: REQS MET? | F9: ACTION NEEDED TO MEET REQ | G9: ACTION OWNER
B11: 4 Context of the organization
B12: 4.1 Understanding the organization and its context | D12: Have the external and internal issues that affect the BCMS been determined? | E12: Yes
D13: Has the organization identified and documented its activities, products and services and relationships, and the potential impact of a disruptive event on them? | E13: Yes
D14: Has the context been defined, in terms of objectives, risk criteria and appetite, and the purpose of the BCMS? | E14: Yes
B15: 4.2 Understanding the needs and expectations of interested parties | C15: 4.2.1 General | D15: Have the interested parties and their requirements been identified? | E15: Yes
C16: 4.2.2 Legal and regulatory requirements | D16: Is there a procedure to identify, document and communicate applicable legal and regulatory requirements? | E16: Yes
D17: Does the BCMS take the applicable legal and regulatory requirements into account? | E17: Yes
B18: 4.3 Determining the scope of the business continuity management system | C18: 4.3.1 General | D18: Has the scope of the BCMS been determined and documented? | E18: Yes
C19: 4.3.2 Scope of the BCMS | D19: Have exclusions to the scope been documented and explained? | E19: Yes
B20: 4.4 Business continuity management system | D20: Is a BCMS in place and being continually improved? | E20: Yes
D22: Total: | E22: =+COUNTIF(E12:E20,"Yes") -> 9
B24: 5 Leadership
B25: 5.1 Leadership and commitment | D25: Does top management demonstrate leadership with respect to the BCMS? | E25: Yes
D26: Does top management demonstrate commitment to the BCMS? | E26: Yes
D27: Is top management commitment evidenced by actions such as providing resources, communicating effectively and setting objectives? | E27: Yes
D28: Has top management allocated responsibility for the BCMS and assigned other relevant BCMS roles? | E28: Yes
B29: 5.2 Policy | C29: 5.2.1 Establishing the business continuity policy | D29: Is a documented business continuity policy in place? | E29: Yes
D30: Does it set objectives for the BCMS? | E30: Yes
D31: Does it commit the organization to satisfying requirements and continually improving the BCMS? | E31: Yes
C32: 5.2.2 Communicating the business continuity policy | D32: Is it adequately communicated and reviewed? | E32: Yes
B33: 5.3 Roles, responsibilities and authorities | D33: Are roles, responsibilities and authorities for the BCMS defined, allocated and communicated? | E33: Yes
D35: Total: | E35: =+COUNTIF(E25:E33,"Yes") -> 9
B37: 6 Planning
B38: 6.1 Actions to address risks and opportunities | C38: 6.1.1 Determining risks and opportunities | D38: Does the plan for the BCMS take into account the relevant issues and requirements? | E38: Yes
D39: Are all of the relevant risks and opportunities determined? | E39: Yes
C40: 6.1.2 Addressing risks and opportunities | D40: Are actions planned to address the identified risks and opportunities? | E40: Yes
B41: 6.2 Business continuity objectives and plans to achieve them | C41: 6.2.1 Establishing business continuity objectives | D41: Have measurable business continuity objectives been established and communicated? | E41: Yes
C42: 6.2.2 Determining business continuity objectives | D42: Is there a plan to achieve the defined business continuity objectives? | E42: Yes
D43: Is success against the objectives reviewed and updated regularly? | E43: Yes
B44: 6.3 Planning changes to the business continuity management system | D44: Are changes to the BCMS carried out in a planned manner? | E44: Yes
D46: Total: | E46: =+COUNTIF(E38:E44,"Yes") -> 7
B48: 7 Support
B49: 7.1 Resources | D49: Are BCMS resources determined and provided? | E49: Yes
B50: 7.2 Competence | D50: Are all of the relevant people sufficiently competent to perform their roles? | E50: Yes
D51: Where necessary, is action taken to improve competence and are records kept? | E51: Yes
B52: 7.3 Awareness | D52: Are all relevant people aware of the business continuity policy and their role during disruptive incidents? | E52: Yes
B53: 7.4 Communication | D53: Is effective internal and external communication in place? | E53: Yes
...

Sheet Dashboard
B8: ISO22301 Gap Assessment dashboard
B9: To refresh chart data, click on “Refresh All” on the Data ribbon.
B11: Gap assessment results
B13: AREA OF STANDARD | C13: REQS IN SECTION | D13: NO OF REQS MET | E13: PERCENTAGE CONFORMITY | G13: Percentage conformity to the ISO22301 standard radar chart
B14: 4 Context of the organization | C14: 9 | D14: ='ISO22301 Gap Assessment'!E22 -> 9 | E14: =+D14/C14 -> 1
B15: 5 Leadership | C15: 9 | D15: ='ISO22301 Gap Assessment'!E35 -> 9 | E15: =+D15/C15 -> 1
B16: 6 Planning | C16: 7 | D16: ='ISO22301 Gap Assessment'!E46 -> 7 | E16: =+D16/C16 -> 1
B17: 7 Support | C17: 10 | D17: ='ISO22301 Gap Assessment'!E60 -> 10 | E17: =+D17/C17 -> 1
B18: 8 Operation | C18: 25 | D18: ='ISO22301 Gap Assessment'!E89 -> 25 | E18: =+D18/C18 -> 1
B19: 9 Performance evaluation | C19: 8 | D19: ='ISO22301 Gap Assessment'!E101 -> 8 | E19: =+D19/C19 -> 1
B20: 10 Improvement | C20: 3 | D20: ='ISO22301 Gap Assessment'!E108 -> 3 | E20: =+D20/C20 -> 1
B21: Total | C21: =SUBTOTAL(109,Table25[REQS IN SECTION]) -> 71 | D21: =SUBTOTAL(109,Table25[NO OF REQS MET]) -> 71 | E21: =IMDIV(D21,C21)*1 -> 1
B24: Level of conformity to the ISO22301 standard
G36: Percentage conformity to the ISO22301 standard

Sheet Conformity Table
B4: Gap assessment results
B6: AREA OF STANDARD | C6: REQS IN SECTION | D6: NO OF REQS MET | E6: PERCENTAGE CONFORMITY
B7: 4 Context of the organization | C7: 9 | D7: ='ISO22301 Gap Assessment'!E22 -> 9 | E7: =+D7/C7 -> 1
B8: 5 Leadership | C8: 9 | D8: ='ISO22301 Gap Assessment'!E35 -> 9 | E8: =+D8/C8 -> 1
B9: 6 Planning | C9: 7 | D9: ='ISO22301 Gap Assessment'!E46 -> 7 | E9: =+D9/C9 -> 1
B10: 7 Support | C10: 10 | D10: ='ISO22301 Gap Assessment'!E60 -> 10 | E10: =+D10/C10 -> 1
B11: 8 Operation | C11: 25 | D11: ='ISO22301 Gap Assessment'!E89 -> 25 | E11: =+D11/C11 -> 1
B12: 9 Performance evaluation | C12: 8 | D12: ='ISO22301 Gap Assessment'!E101 -> 8 | E12: =+D12/C12 -> 1
B13: 10 Improvement | C13: 3 | D13: ='ISO22301 Gap Assessment'!E108 -> 3 | E13: =+D13/C13 -> 1
B14: Total | C14: =SUBTOTAL(109,Table2[REQS IN SECTION]) -> 71 | D14: =SUBTOTAL(109,Table2[NO OF REQS MET]) -> 71 | E14: =IMDIV(D14,C14)*1 -> 1

Sheet Conformity Chart Pivot
B4: Level of Conformity to ISO22301 Standard
B6: AREA OF STANDARD | C6: REQS IN SECTION | D6: NO OF REQS MET
B7: 10 Improvement | C7: 3 | D7: 3
B8: 9 Performance evaluation | C8: 8 | D8: 8
B9: 8 Operation | C9: 25 | D9: 25
B10: 7 Support | C10: 10 | D10: 10
B11: 6 Planning | C11: 7 | D11: 7
B12: 5 Leadership | C12: 9 | D12: 9
B13: 4 Context of the organization | C13: 9 | D13: 9

Sheet % Conformity Chart Pivot
B4: Percentage Conformity to the ISO22301 Standard
B6: AREA OF STANDARD | C6: PERCENTAGE CONFORMANT
B7: 4 Context of the organization | C7: 1
B8: 5 Leadership | C8: 1
B9: 6 Planning | C9: 1
B10: 7 Support | C10: 1
B11: 8 Operation | C11: 1
B12: 9 Performance evaluation | C12: 1
B13: 10 Improvement | C13: 1

Sheet % Conformity Radar Pivot
B4: Percentage Conformity to the ISO22301 Standard Radar Chart
B6: AREA OF STANDARD | C6: PERCENTAGE CONFORMITY
B7: 4 Context of the organization | C7: 1
B8: 5 Leadership | C8: 1
B9: 6 Planning | C9: 1
B10: 7 Support | C10: 1
B11: 8 Operation | C11: 1
B12: 9 Performance evaluation | C12: 1
B13: 10 Improvement | C13: 1
