Workbook

Sheet Guidance
B8: Implementation Guidance This Excel sheet must be removed from the final version of the document.
B10: Design This spreadsheet has been designed using CertiKit's colour scheme. To choose a different table colour scheme, click in the table, select the Table Design menu tab and choose a different style. The same applies to the drop-down menu "slicers" at the top of the screen. Click in one slicer, then hold down the Shift key and click on the rest, one by one. This will select them all. Then click on the Slicer menu tab and choose a different style. You can also create your own table and slicer styles using your own colour scheme to reflect your organization's branding.
B12: Purpose of this document This workbook identifies the key business continuity requirements for each critical business activity.
B14: Areas of the standard addressed The main areas of the ISO22301 standard addressed by this workbook are: 8. Operation 8.2 Business impact analysis and risk assessment 8.2.2 Business impact analysis
B16: General guidance This is a key document which underpins your business continuity strategies and plans. You should invest a significant amount of time in ensuring that this analysis is complete and correct. Following the business impact analysis process, you will need to work through each of the worksheets with representatives from each team involved in the critical business activities. This is probably best done in a series of facilitated workshops supported by clear top management commitment. A maximum of ten business activities are catered for in this tool; if you need more, copy the relevant tables to the end of each tab.
B18: Review frequency We would recommend that this document is reviewed at least annually and upon major changes to business operations or other relevant factors.
B20: Toolkit version number ISO22301 Toolkit Version 6
B22: Copyright notice Except for any specifically identified third-party works included, this document has been authored by CertiKit, and is ©CertiKit except as stated below. CertiKit is a company registered in England and Wales with company number 6432088.
B24: Licence terms This document is licensed on and subject to the standard licence terms of CertiKit, available on request, or by download from our website. All other rights are reserved. Unless you have purchased this product you only have an evaluation licence. If this product was purchased, a full licence is granted to the person identified as the licensee in the relevant purchase order. The standard licence terms include special terms relating to any third party copyright included in this document.
B26: Disclaimer Please Note: Your use of and reliance on this document template is at your sole risk. Document templates are intended to be used as a starting point only from which you will create your own document and to which you will apply all reasonable quality checks before use. Therefore please note that it is your responsibility to ensure that the content of any document you create that is based on our templates is correct and appropriate for your needs and complies with relevant laws in your country. You should take all reasonable and proper legal and other professional advice before using this document. CertiKit makes no claims, promises, or guarantees about the accuracy, completeness, or adequacy of our document templates, assumes no duty of care to any person with respect its document templates or their contents, and expressly excludes and disclaims liability for any cost, expense, loss or damage suffered or incurred in reliance on our document templates, or in expectation of our document templates meeting your needs, including (without limitation) as a result of misstatements, errors and omissions in their contents.

Sheet Definitions
B8: Terms and Definitions
B9: The following definitions are taken from ISO22301 and ISO22300.
B11: TERM | C11: DEFINITION
B12: Activity | C12: Process or set of processes undertaken by an organization (or on its behalf) that produces or supports one or more products and services. For example, such processes include accounts, call centre, IT, manufacture and distribution.
B14: Business impact analysis | C14: Process of analysing activities and the effect that a business disruption might have upon them.
B16: Maximum acceptable outage (MAO) | C16: Time it would take for adverse impacts, which might arise as a result of not providing a product/service or performing an activity, to become unacceptable (see also MTPD).
B18: Maximum tolerable period of disruption (MTPD) | C18: Time it would take for adverse impacts, which might arise as a result of not providing a product/service or performing an activity, to become unacceptable (see also MAO).
B20: Minimum business continuity objective (MBCO) | C20: Minimum level of services and/or products that is acceptable to the organization to achieve its business objectives during a disruption.
B22: Products and services | C22: Beneficial outcomes provided by an organization to its customers, recipients and interested parties, e.g. manufactured items, car insurance and community nursing.
B24: Prioritised activities | C24: Activities to which priority must be given following an incident in order to mitigate impacts.
B26: Recovery point objective (RPO) | C26: Point to which information used by an activity must be restored to enable the activity to operate on resumption NOTE - can also be referred to as "maximum data loss".
B28: Recovery time objective (RTO) | C28: Period of time following an incident within which a)product or service must be resumed or b) activity must be resumed or c) resources must be recovered NOTE - for products, services and activities, the recovery time objective must be less than the time it would take for the adverse impacts that would arise as a result of not providing a product/service or performing an activity to become unacceptable.

Sheet Analysis Details
B8: Business Impact Analysis Details
B10: Business Impact Analysis Title | C10: [Short, descriptive title]
B11: Business Impact Analysis Scope | C11: [Describe the scope of the BIA, such as organizational area, location, processes]
B12: Context of Business Impact Analysis | C12: [Describe the general environment in which the analysis is carried out and internal and external factors affecting it]
B13: Version | C13: [Start at Version 1]
B14: Dated | C14: [Date the analysis was carried out]
B15: Lead Analyst(s) | C15: [Names and titles of person(s) carrying out the BIA]
B16: Business Impact Analysis Participants | C16: [Names and titles of people contributing to the BIA]
B17: Approval | C17: [Name and title of approver]
B18: Date Approved | C18: [Date the analysis was approved]

Sheet Key Business Activities
B8: Identification of Key Business Activities
B9: [List all the key business activities within the scope of the analysis exercise and their requirements]
D11: RESOURCES USUALLY NEEDED FOR THIS ACTIVITY TO OCCUR
B12: Ref | C12: Business activity | D12: People | E12: Information and data | F12: Buildings, work environment and utilities | G12: Facilities, equipment and consumables | H12: ICT systems | I12: Transportation | J12: Finance | K12: Partners and suppliers | L12: Outcome of delivered activity | M12: Any legal, statutory and contractual obligations
B13: 1
B14: 2
B15: 3
B16: 4
B17: 5
B18: 6
B19: 7
B20: 8
B21: 9
B22: 10

Sheet Impact of Disruption
B8: Impact of Disruption
B9: [For each key business activity, assess the impact of unavailability over time in each area. For example, customers, finance]
B11: REFERENCE: [Impact 1] | D11: BUSINESS ACTIVITY: | E11: =IF(ISBLANK(+'Key Business Activities'!C13),"[Business activity]",+'Key Business Activities'!C13) -> [Business activity]
B12: Time | C12: Impact on staff or public well-being | D12: Impact of breaching legal or regulatory requirements | E12: Damage to reputation | F12: Impact on financial viability | G12: Impact on product or service quality | H12: Environmental damage | I12: Total score
B13: One hour | C13: Select… | D13: Select… | E13: Select… | F13: Select… | G13: Select… | H13: Select… | I13: =SUM(Impact1[[#This Row],[Impact on staff or public well-being]:[Environmental damage]]) -> 0
B14: Three hours | C14: Select… | D14: Select… | E14: Select… | F14: Select… | G14: Select… | H14: Select… | I14: =SUM(Impact1[[#This Row],[Impact on staff or public well-being]:[Environmental damage]]) -> 0
B15: One day | C15: Select… | D15: Select… | E15: Select… | F15: Select… | G15: Select… | H15: Select… | I15: =SUM(Impact1[[#This Row],[Impact on staff or public well-being]:[Environmental damage]]) -> 0
B16: Three days | C16: Select… | D16: Select… | E16: Select… | F16: Select… | G16: Select… | H16: Select… | I16: =SUM(Impact1[[#This Row],[Impact on staff or public well-being]:[Environmental damage]]) -> 0
B17: One week | C17: Select… | D17: Select… | E17: Select… | F17: Select… | G17: Select… | H17: Select… | I17: =SUM(Impact1[[#This Row],[Impact on staff or public well-being]:[Environmental damage]]) -> 0
B18: One month | C18: Select… | D18: Select… | E18: Select… | F18: Select… | G18: Select… | H18: Select… | I18: =SUM(Impact1[[#This Row],[Impact on staff or public well-being]:[Environmental damage]]) -> 0
B20: Key: 1 (low) to 5 (high) | G20: COMPLETED BY: | H20: [Enter name here]
G21: DATE: | H21: [Enter date here]
B24: REFERENCE: [Impact 2] | D24: BUSINESS ACTIVITY: | E24: =IF(ISBLANK(+'Key Business Activities'!C14),"[Business activity]",+'Key Business Activities'!C14) -> [Business activity]
B25: Time | C25: Impact on staff or public well-being | D25: Impact of breaching legal or regulatory requirements | E25: Damage to reputation | F25: Impact on financial viability | G25: Impact on product or service quality | H25: Environmental damage | I25: Total score
B26: One hour | C26: Select… | D26: Select… | E26: Select… | F26: Select… | G26: Select… | H26: Select… | I26: =SUM(Impact2[[#This Row],[Impact on staff or public well-being]:[Environmental damage]]) -> 0
B27: Three hours | C27: Select… | D27: Select… | E27: Select… | F27: Select… | G27: Select… | H27: Select… | I27: =SUM(Impact2[[#This Row],[Impact on staff or public well-being]:[Environmental damage]]) -> 0
B28: One day | C28: Select… | D28: Select… | E28: Select… | F28: Select… | G28: Select… | H28: Select… | I28: =SUM(Impact2[[#This Row],[Impact on staff or public well-being]:[Environmental damage]]) -> 0
B29: Three days | C29: Select… | D29: Select… | E29: Select… | F29: Select… | G29: Select… | H29: Select… | I29: =SUM(Impact2[[#This Row],[Impact on staff or public well-being]:[Environmental damage]]) -> 0
B30: One week | C30: Select… | D30: Select… | E30: Select… | F30: Select… | G30: Select… | H30: Select… | I30: =SUM(Impact2[[#This Row],[Impact on staff or public well-being]:[Environmental damage]]) -> 0
B31: One month | C31: Select… | D31: Select… | E31: Select… | F31: Select… | G31: Select… | H31: Select… | I31: =SUM(Impact2[[#This Row],[Impact on staff or public well-being]:[Environmental damage]]) -> 0
B33: Key: 1 (low) to 5 (high) | G33: COMPLETED BY: | H33: [Enter name here]
G34: DATE: | H34: [Enter date here]
B37: REFERENCE: [Impact 3] | D37: BUSINESS ACTIVITY: | E37: =IF(ISBLANK(+'Key Business Activities'!C15),"[Business activity]",+'Key Business Activities'!C15) -> [Business activity]
B38: Time | C38: Impact on staff or public well-being | D38: Impact of breaching legal or regulatory requirements | E38: Damage to reputation | F38: Impact on financial viability | G38: Impact on product or service quality | H38: Environmental damage | I38: Total score
B39: One hour | C39: Select… | D39: Select… | E39: Select… | F39: Select… | G39: Select… | H39: Select… | I39: =SUM(Impact3[[#This Row],[Impact on staff or public well-being]:[Environmental damage]]) -> 0
B40: Three hours | C40: Select… | D40: Select… | E40: Select… | F40: Select… | G40: Select… | H40: Select… | I40: =SUM(Impact3[[#This Row],[Impact on staff or public well-being]:[Environmental damage]]) -> 0
B41: One day | C41: Select… | D41: Select… | E41: Select… | F41: Select… | G41: Select… | H41: Select… | I41: =SUM(Impact3[[#This Row],[Impact on staff or public well-being]:[Environmental damage]]) -> 0
B42: Three days | C42: Select… | D42: Select… | E42: Select… | F42: Select… | G42: Select… | H42: Select… | I42: =SUM(Impact3[[#This Row],[Impact on staff or public well-being]:[Environmental damage]]) -> 0
B43: One week | C43: Select… | D43: Select… | E43: Select… | F43: Select… | G43: Select… | H43: Select… | I43: =SUM(Impact3[[#This Row],[Impact on staff or public well-being]:[Environmental damage]]) -> 0
B44: One month | C44: Select… | D44: Select… | E44: Select… | F44: Select… | G44: Select… | H44: Select… | I44: =SUM(Impact3[[#This Row],[Impact on staff or public well-being]:[Environmental damage]]) -> 0
B46: Key: 1 (low) to 5 (high) | G46: COMPLETED BY: | H46: [Enter name here]
G47: DATE: | H47: [Enter date here]
B50: REFERENCE: [Impact 4] | D50: BUSINESS ACTIVITY: | E50: =IF(ISBLANK(+'Key Business Activities'!C16),"[Business activity]",+'Key Business Activities'!C16) -> [Business activity]
B51: Time | C51: Impact on staff or public well-being | D51: Impact of breaching legal or regulatory requirements | E51: Damage to reputation | F51: Impact on financial viability | G51: Impact on product or service quality | H51: Environmental damage | I51: Total score
B52: One hour | C52: Select… | D52: Select… | E52: Select… | F52: Select… | G52: Select… | H52: Select… | I52: =SUM(Impact4[[#This Row],[Impact on staff or public well-being]:[Environmental damage]]) -> 0
B53: Three hours | C53: Select… | D53: Select… | E53: Select… | F53: Select… | G53: Select… | H53: Select… | I53: =SUM(Impact4[[#This Row],[Impact on staff or public well-being]:[Environmental damage]]) -> 0
B54: One day | C54: Select… | D54: Select… | E54: Select… | F54: Select… | G54: Select… | H54: Select… | I54: =SUM(Impact4[[#This Row],[Impact on staff or public well-being]:[Environmental damage]]) -> 0
B55: Three days | C55: Select… | D55: Select… | E55: Select… | F55: Select… | G55: Select… | H55: Select… | I55: =SUM(Impact4[[#This Row],[Impact on staff or public well-being]:[Environmental damage]]) -> 0
B56: One week | C56: Select… | D56: Select… | E56: Select… | F56: Select… | G56: Select… | H56: Select… | I56: =SUM(Impact4[[#This Row],[Impact on staff or public well-being]:[Environmental damage]]) -> 0
B57: One month | C57: Select… | D57: Select… | E57: Select… | F57: Select… | G57: Select… | H57: Select… | I57: =SUM(Impact4[[#This Row],[Impact on staff or public well-being]:[Environmental damage]]) -> 0
...

Sheet Key Targets
B8: Key Business Continuity Targets
B9: [For each key business activity, state the MTPD, RTO, MBCO and RPO]. See panel, right, for key.
B11: REF | C11: BUSINESS ACTIVITY | D11: MTPD | E11: RTO | F11: MBCO | G11: RPO | I11: Key to terms MTPD (Maximum Tolerable Period of Disruption), when any one impact scores four or more: Time it would take for adverse impacts, which might arise as a result of not providing a product/service or performing an activity, to become unacceptable (see also MAO). RTO (Recovery Time Objective): Period of time following an incident within which a) product or service must be resumed or b) activity must be resumed or c) resources must be recovered. MBCO (Minimum Business Continuity Objective): Minimum level of services and/or products that is acceptable to the organization to achieve its business objectives during a disruption. RPO (Recovery Point Objective): Point to which information used by an activity must be restored to enable the activity to operate on resumption.
B12: 1 | C12: =IF(ISBLANK(+'Key Business Activities'!C13),"[Business activity]",+'Key Business Activities'!C13) -> [Business activity]
B13: 2 | C13: =IF(ISBLANK(+'Key Business Activities'!C14),"[Business activity]",+'Key Business Activities'!C14) -> [Business activity]
B14: 3 | C14: =IF(ISBLANK(+'Key Business Activities'!C15),"[Business activity]",+'Key Business Activities'!C15) -> [Business activity]
B15: 4 | C15: =IF(ISBLANK(+'Key Business Activities'!C16),"[Business activity]",+'Key Business Activities'!C16) -> [Business activity]
B16: 5 | C16: =IF(ISBLANK(+'Key Business Activities'!C17),"[Business activity]",+'Key Business Activities'!C17) -> [Business activity]
B17: 6 | C17: =IF(ISBLANK(+'Key Business Activities'!C18),"[Business activity]",+'Key Business Activities'!C18) -> [Business activity]
B18: 7 | C18: =IF(ISBLANK(+'Key Business Activities'!C19),"[Business activity]",+'Key Business Activities'!C19) -> [Business activity]
B19: 8 | C19: =IF(ISBLANK(+'Key Business Activities'!C20),"[Business activity]",+'Key Business Activities'!C20) -> [Business activity]
B20: 9 | C20: =IF(ISBLANK(+'Key Business Activities'!C21),"[Business activity]",+'Key Business Activities'!C21) -> [Business activity]
B21: 10 | C21: =IF(ISBLANK(+'Key Business Activities'!C22),"[Business activity]",+'Key Business Activities'!C22) -> [Business activity]

Sheet Dependencies and Recovery Needs
B8: Dependencies and Recovery Needs
B9: [For each key business activity list the dependencies at each time period, starting from the relevant RTO. Then calculate the total requirement across the time periods]
B10: [Note: where cells are automatically populated from other sections of the tool, make sure you expand the cells to show all of their contents.]
B12: Total requirement
B14: REFERENCE: All | C14: BUSINESS ACTIVITY: | D14: All
B15: Dependency | C15: Normal requirement | D15: One hour | E15: Three hours | F15: One day | G15: Three days | H15: One week | I15: One month
B16: People
B17: Information and data
B18: Buildings, work environment and utilities
B19: Facilities, equipment and consumables
B20: ICT systems
B21: Transportation
B22: Finance
B23: Partners and suppliers
G25: COMPLETED BY: | H25: [Enter name here]
G26: DATE: | H26: [Enter date here]
B27: Requirements per business activity
B29: REFERENCE: [DepRec 1] | C29: BUSINESS ACTIVITY: | D29: =IF(ISBLANK(+'Key Business Activities'!C13),"[Business activity]",+'Key Business Activities'!C13) -> [Business activity]
B30: Dependency | C30: Normal requirement | D30: One hour | E30: Three hours | F30: One day | G30: Three days | H30: One week | I30: One month
B31: People | C31: =IF(ISBLANK(+'Key Business Activities'!D13),"[Normal Requirement]",+'Key Business Activities'!D13) -> [Normal Requirement]
B32: Information and data | C32: =IF(ISBLANK(+'Key Business Activities'!E13),"[Normal Requirement]",+'Key Business Activities'!E13) -> [Normal Requirement]
B33: Buildings, work environment and utilities | C33: =IF(ISBLANK(+'Key Business Activities'!F13),"[Normal Requirement]",+'Key Business Activities'!F13) -> [Normal Requirement]
B34: Facilities, equipment and consumables | C34: =IF(ISBLANK(+'Key Business Activities'!G13),"[Normal Requirement]",+'Key Business Activities'!G13) -> [Normal Requirement]
B35: ICT systems | C35: =IF(ISBLANK(+'Key Business Activities'!H13),"[Normal Requirement]",+'Key Business Activities'!H13) -> [Normal Requirement]
B36: Transportation | C36: =IF(ISBLANK(+'Key Business Activities'!I13),"[Normal Requirement]",+'Key Business Activities'!I13) -> [Normal Requirement]
B37: Finance | C37: =IF(ISBLANK(+'Key Business Activities'!J13),"[Normal Requirement]",+'Key Business Activities'!J13) -> [Normal Requirement]
B38: Partners and suppliers | C38: =IF(ISBLANK(+'Key Business Activities'!K13),"[Normal Requirement]",+'Key Business Activities'!K13) -> [Normal Requirement]
G40: RTO: | H40: =IF(ISBLANK(+'Key Targets'!E12),"[RTO]",+'Key Targets'!E12) -> [RTO]
G41: MBCO: | H41: =IF(ISBLANK(+'Key Targets'!F12),"[MBCO]",+'Key Targets'!F12) -> [MBCO]
B44: REFERENCE: [DepRec 2] | C44: BUSINESS ACTIVITY: | D44: =IF(ISBLANK(+'Key Business Activities'!C14),"[Business activity]",+'Key Business Activities'!C14) -> [Business activity]
B45: Dependency | C45: Normal requirement | D45: One hour | E45: Three hours | F45: One day | G45: Three days | H45: One week | I45: One month
B46: People | C46: =IF(ISBLANK(+'Key Business Activities'!D14),"[Normal Requirement]",+'Key Business Activities'!D14) -> [Normal Requirement]
B47: Information and data | C47: =IF(ISBLANK(+'Key Business Activities'!E14),"[Normal Requirement]",+'Key Business Activities'!E14) -> [Normal Requirement]
B48: Buildings, work environment and utilities | C48: =IF(ISBLANK(+'Key Business Activities'!F14),"[Normal Requirement]",+'Key Business Activities'!F14) -> [Normal Requirement]
B49: Facilities, equipment and consumables | C49: =IF(ISBLANK(+'Key Business Activities'!G14),"[Normal Requirement]",+'Key Business Activities'!G14) -> [Normal Requirement]
B50: ICT systems | C50: =IF(ISBLANK(+'Key Business Activities'!H14),"[Normal Requirement]",+'Key Business Activities'!H14) -> [Normal Requirement]
B51: Transportation | C51: =IF(ISBLANK(+'Key Business Activities'!I14),"[Normal Requirement]",+'Key Business Activities'!I14) -> [Normal Requirement]
B52: Finance | C52: =IF(ISBLANK(+'Key Business Activities'!J14),"[Normal Requirement]",+'Key Business Activities'!J14) -> [Normal Requirement]
B53: Partners and suppliers | C53: =IF(ISBLANK(+'Key Business Activities'!K14),"[Normal Requirement]",+'Key Business Activities'!K14) -> [Normal Requirement]
G55: RTO: | H55: =IF(ISBLANK(+'Key Targets'!E13),"[RTO]",+'Key Targets'!E13) -> [RTO]
...

Sheet Priority List
B8: Recovery Priority List
B9: [List the key business activities in order of recovery priority, together with the Recovery Time Objective and Minimum Business Continuity Objectives required]
B11: REF | C11: BUSINESS ACTIVITY | D11: RTO | E11: MBCO REQUIREMENTS AT RTO
B12: 1
B13: 2
B14: 3
B15: 4
B16: 5
B17: 6
B18: 7
B19: 8
B20: 9
B21: 10

Sheet Tables
A1: ONE TO FIVE
A2: Select…
A3: 1
A4: 2
A5: 3
A6: 4
A7: 5
