Workbook

Sheet Definitions
B8: Terms and Definitions
B9: The following definitions are taken from ISO22301 and ISO22300.
B11: TERM | C11: DEFINITION
B12: Activity | C12: Process or set of processes undertaken by an organization (or on its behalf) that produces or supports one or more products and services. For example, such processes include accounts, call centre, IT, manufacture and distribution.
B14: Business impact analysis | C14: Process of analysing activities and the effect that a business disruption might have upon them.
B16: Maximum acceptable outage (MAO) | C16: Time it would take for adverse impacts, which might arise as a result of not providing a product/service or performing an activity, to become unacceptable (see also MTPD).
B18: Maximum tolerable period of disruption (MTPD) | C18: Time it would take for adverse impacts, which might arise as a result of not providing a product/service or performing an activity, to become unacceptable (see also MAO).
B20: Minimum business continuity objective (MBCO) | C20: Minimum level of services and/or products that is acceptable to the organization to achieve its business objectives during a disruption.
B22: Products and services | C22: Beneficial outcomes provided by an organization to its customers, recipients and interested parties, e.g. manufactured items, car insurance and community nursing.
B24: Prioritised activities | C24: Activities to which priority must be given following an incident in order to mitigate impacts.
B26: Recovery point objective (RPO) | C26: Point to which information used by an activity must be restored to enable the activity to operate on resumption NOTE - can also be referred to as "maximum data loss".
B28: Recovery time objective (RTO) | C28: Period of time following an incident within which a)product or service must be resumed or b) activity must be resumed or c) resources must be recovered NOTE - for products, services and activities, the recovery time objective must be less than the time it would take for the adverse impacts that would arise as a result of not providing a product/service or performing an activity to become unacceptable.

Sheet Analysis Details
B8: Business Impact Analysis Details
B10: Business Impact Analysis Title | C10: Initial company-wide BIA
B11: Business Impact Analysis Scope | C11: All major departments of the business.
B12: Context of Business Impact Analysis | C12: The company has grown significantly over the last 12 months and the amount of revenue being generated in some areas makes them more business-critical. Customer expectations have also increased. The legal framework is now more rigorous and the consequences of failure are more expensive.
B13: Version | C13: 1
B14: Dated | C14: 24 January 20xx
B15: Lead Analyst(s) | C15: A. N. Other
B16: Business Impact Analysis Participants | C16: John Smith, Marketing Manager David Brown, Head of Human Resources Joanne Green, Customer Services Manager Daljit Singh, Finance Manager Jack Grimshaw, Head of Manufacturing Jason Hooper, Product Development Manager
B17: Approval | C17: Jack Spielberg, Chief Operating Officer
B18: Date Approved | C18: January 31, 20xx

Sheet Key Business Activities
B8: Identification of Key Business Activities
B9: [List all the key business activities within the scope of the analysis exercise and their requirements]
D11: RESOURCES USUALLY NEEDED FOR THIS ACTIVITY TO OCCUR
B12: Ref | C12: Business activity | D12: People | E12: Information and data | F12: Buildings, work environment and utilities | G12: Facilities, equipment and consumables | H12: ICT systems | I12: Transportation | J12: Finance | K12: Partners and suppliers | L12: Outcome of delivered activity | M12: Any legal, statutory and contractual obligations
B13: 1 | C13: Sales and Marketing | D13: Head of Sales and Marketing 3 x sales representatives 2 x marketing managers | E13: Customer database Marketing database | F13: 6 desks in HQ building, power and HVAC | G13: 3 desktop computers, 3 laptops with access to printer, copier, scanner and fax | H13: CRM system Email Internet access | I13: Commuting from home to work and back Sales visits by car | J13: Expenses and payroll | K13: Telemarketing bureau | L13: Product sales to new and existing customers | M13: Comply with marketing legislation
B14: 2 | C14: Finance | D14: Head of Finance 6 in team | E14: Accounting database | F14: 7 desks in HQ building, power and HVAC | G14: 7 desktop computers with access to printer, copier, scanner and fax | H14: Finance system Email Internet access | I14: Commuting from home to work and back | J14: Access to company bank account to pay suppliers and employees | K14: Cloud accounting system providers Tax agency | L14: Payments to suppliers Payments received Statutory accounts created | M14: Contractual payment terms Tax obligations
B15: 3 | C15: Human Resources | D15: Human Resources Manager 3 people in team 1 trainer | E15: Employee records Training records Payroll data | F15: 5 desks in HQ building, power and HVAC | G15: 5 desktop computers with access to printer, copier, scanner and fax | H15: HR system Email Payroll system Internet access eLearning system | I15: Commuting from home to work and back | J15: Operational expenses | K15: Occupational health provider Payroll bureau | L15: Employees salaries paid Expenses paid Training delivered Employee welfare managed | M15: Health and safety law Tax obligations Pension law Employee contracts Data protection law
B16: 4 | C16: Manufacturing | D16: Manufacturing Manager 30 shop-floor staff | E16: Process documentation Product sheets | F16: Purpose-built manufacturing plant with limited office accommodation, significant power requirements | G16: 2 desktop computers with access to printer, copier, scanner and fax | H16: Manufacturing control system Limited access to email | I16: Commuting from home to work and back | J16: Operational expenses Petty cash | K16: Wide range of component suppliers | L16: Products created to fulfil orders | M16: Health and safety law Contractual delivery times
B17: 5 | C17: Customer Services | D17: Customer Services Manager 2 x CS Supervisors 12 CS representatives | E17: Customer database Appointments information Product information | F17: 15 desks in HQ building, power and HVAC. Post room | G17: 15 desktop computers with access to printer, copier, scanner and fax | H17: CRM system Email Internet access Website admin | I17: Commuting from home to work and back | J17: Operational expenses | K17: Various commodity suppliers | L17: Customer enquiries answered Customer support delivered | M17: Product support obligations
B18: 6 | C18: Product Development | D18: Head of Product Development 4 x product managers | E18: Product plans Product designs Testing information | F18: 5 desks in HQ building, power and HVAC. Test area | G18: 6 desktop computers with access to printer, copier, scanner and fax | H18: Design software Email Internet access | I18: Commuting from home to work and back | J18: Operational expenses Purchase of test components | K18: Partner with software company | L18: New products created | M18: Customer contractual obligations
B19: 7 | C19: Website sales | D19: 2 x website developers | E19: Product information Pricing | F19: Hosted with third party | G19: 2 desktop computers with access to printer, copier, scanner and fax | H19: Content management system | I19: None | J19: Operational expenses | K19: Website hosting company | L19: Sales via website | M19: Distance selling regulations
B20: 8
B21: 9
B22: 10

Sheet Impact of Disruption
B8: Impact of Disruption
B9: [For each key business activity, assess the impact of unavailability over time in each area. For example, customers, finance]
B11: REFERENCE: [Impact 1] | D11: BUSINESS ACTIVITY: | E11: =IF(ISBLANK(+'Key Business Activities'!C13),"[Business activity]",+'Key Business Activities'!C13) -> Sales and Marketing
B12: Time | C12: Impact on staff or public well-being | D12: Impact of breaching legal or regulatory requirements | E12: Damage to reputation | F12: Impact on financial viability | G12: Impact on product or service quality | H12: Environmental damage | I12: Total score
B13: One hour | C13: 1 | D13: 1 | E13: 1 | F13: 1 | G13: 1 | H13: 1 | I13: 6
B14: Three hours | C14: 1 | D14: 1 | E14: 1 | F14: 1 | G14: 1 | H14: 1 | I14: 6
B15: One day | C15: 1 | D15: 1 | E15: 1 | F15: 2 | G15: 1 | H15: 1 | I15: 7
B16: Three days | C16: 2 | D16: 1 | E16: 2 | F16: 2 | G16: 1 | H16: 1 | I16: 9
B17: One week | C17: 2 | D17: 1 | E17: 2 | F17: 2 | G17: 1 | H17: 1 | I17: 9
B18: One month | C18: 3 | D18: 1 | E18: 3 | F18: 4 | G18: 1 | H18: 1 | I18: 13
B20: Key: 1 (low) to 5 (high) | G20: COMPLETED BY: | H20: John Smith
G21: DATE: | H21: January 24, 20xx
B24: REFERENCE: [Impact 2] | D24: BUSINESS ACTIVITY: | E24: =IF(ISBLANK(+'Key Business Activities'!C14),"[Business activity]",+'Key Business Activities'!C14) -> Finance
B25: Time | C25: Impact on staff or public well-being | D25: Impact of breaching legal or regulatory requirements | E25: Damage to reputation | F25: Impact on financial viability | G25: Impact on product or service quality | H25: Environmental damage | I25: Total score
B26: One hour | C26: 1 | D26: 1 | E26: 1 | F26: 1 | G26: 1 | H26: 1 | I26: 6
B27: Three hours | C27: 1 | D27: 1 | E27: 1 | F27: 1 | G27: 1 | H27: 1 | I27: 6
B28: One day | C28: 1 | D28: 1 | E28: 1 | F28: 2 | G28: 1 | H28: 1 | I28: 7
B29: Three days | C29: 2 | D29: 2 | E29: 2 | F29: 3 | G29: 1 | H29: 1 | I29: 11
B30: One week | C30: 2 | D30: 3 | E30: 3 | F30: 4 | G30: 2 | H30: 1 | I30: 15
B31: One month | C31: 3 | D31: 4 | E31: 4 | F31: 4 | G31: 2 | H31: 1 | I31: 18
B33: Key: 1 (low) to 5 (high) | G33: COMPLETED BY: | H33: Daljit Singh
G34: DATE: | H34: January 24, 20xx
B37: REFERENCE: [Impact 3] | D37: BUSINESS ACTIVITY: | E37: =IF(ISBLANK(+'Key Business Activities'!C15),"[Business activity]",+'Key Business Activities'!C15) -> Human Resources
B38: Time | C38: Impact on staff or public well-being | D38: Impact of breaching legal or regulatory requirements | E38: Damage to reputation | F38: Impact on financial viability | G38: Impact on product or service quality | H38: Environmental damage | I38: Total score
B39: One hour | C39: 1 | D39: 1 | E39: 1 | F39: 1 | G39: 1 | H39: 1 | I39: 6
B40: Three hours | C40: 1 | D40: 1 | E40: 1 | F40: 1 | G40: 1 | H40: 1 | I40: 6
B41: One day | C41: 2 | D41: 2 | E41: 1 | F41: 1 | G41: 1 | H41: 1 | I41: 8
B42: Three days | C42: 3 | D42: 2 | E42: 2 | F42: 2 | G42: 1 | H42: 1 | I42: 11
B43: One week | C43: 4 | D43: 3 | E43: 2 | F43: 2 | G43: 2 | H43: 2 | I43: 15
B44: One month | C44: 4 | D44: 4 | E44: 3 | F44: 3 | G44: 2 | H44: 2 | I44: 18
B46: Key: 1 (low) to 5 (high) | G46: COMPLETED BY: | H46: David Brown
G47: DATE: | H47: January 24, 20xx
B50: REFERENCE: [Impact 4] | D50: BUSINESS ACTIVITY: | E50: =IF(ISBLANK(+'Key Business Activities'!C16),"[Business activity]",+'Key Business Activities'!C16) -> Manufacturing
B51: Time | C51: Impact on staff or public well-being | D51: Impact of breaching legal or regulatory requirements | E51: Damage to reputation | F51: Impact on financial viability | G51: Impact on product or service quality | H51: Environmental damage | I51: Total score
B52: One hour | C52: 1 | D52: 1 | E52: 2 | F52: 2 | G52: 2 | H52: 2 | I52: 10
B53: Three hours | C53: 1 | D53: 1 | E53: 2 | F53: 3 | G53: 2 | H53: 2 | I53: 11
B54: One day | C54: 2 | D54: 1 | E54: 3 | F54: 3 | G54: 2 | H54: 3 | I54: 14
B55: Three days | C55: 3 | D55: 2 | E55: 3 | F55: 4 | G55: 3 | H55: 3 | I55: 18
B56: One week | C56: 3 | D56: 2 | E56: 4 | F56: 4 | G56: 3 | H56: 3 | I56: 19
B57: One month | C57: 4 | D57: 3 | E57: 4 | F57: 5 | G57: 4 | H57: 3 | I57: 23
...

Sheet Key Targets
B8: Key Business Continuity Targets
B9: [For each key business activity, state the MTPD, RTO, MBCO and RPO]. See panel, right, for key.
B11: REF | C11: BUSINESS ACTIVITY | D11: MTPD | E11: RTO | F11: MBCO | G11: RPO | I11: Key to terms MTPD (Maximum Tolerable Period of Disruption), when any one impact scores four or more: Time it would take for adverse impacts, which might arise as a result of not providing a product/service or performing an activity, to become unacceptable (see also MAO). RTO (Recovery Time Objective): Period of time following an incident within which a) product or service must be resumed or b) activity must be resumed or c) resources must be recovered. MBCO (Minimum Business Continuity Objective): Minimum level of services and/or products that is acceptable to the organization to achieve its business objectives during a disruption. RPO (Recovery Point Objective): Point to which information used by an activity must be restored to enable the activity to operate on resumption.
B12: 1 | C12: =IF(ISBLANK(+'Key Business Activities'!C13),"[Business activity]",+'Key Business Activities'!C13) -> Sales and Marketing | D12: 1 month | E12: 1 month | F12: 50% of normal sales activity | G12: 1 week
B13: 2 | C13: =IF(ISBLANK(+'Key Business Activities'!C14),"[Business activity]",+'Key Business Activities'!C14) -> Finance | D13: 1 week | E13: 3 days | F13: Pay suppliers Receive payments | G13: 1 day
B14: 3 | C14: =IF(ISBLANK(+'Key Business Activities'!C15),"[Business activity]",+'Key Business Activities'!C15) -> Human Resources | D14: 1 week | E14: 3 days | F14: Basic enquiries service | G14: 1 week
B15: 4 | C15: =IF(ISBLANK(+'Key Business Activities'!C16),"[Business activity]",+'Key Business Activities'!C16) -> Manufacturing | D15: 3 days | E15: 3 days | F15: 50% of normal capacity | G15: 1 day
B16: 5 | C16: =IF(ISBLANK(+'Key Business Activities'!C17),"[Business activity]",+'Key Business Activities'!C17) -> Customer Services | D16: 3 days | E16: 3 days | F16: Half of normal service level | G16: 1 day
B17: 6 | C17: =IF(ISBLANK(+'Key Business Activities'!C18),"[Business activity]",+'Key Business Activities'!C18) -> Product Development | D17: 1 month + | E17: 1 month | F17: Key products only | G17: 1 week
B18: 7 | C18: =IF(ISBLANK(+'Key Business Activities'!C19),"[Business activity]",+'Key Business Activities'!C19) -> Website sales | D18: 1 day | E18: 3 hours | F18: Normal service | G18: As close to point of failure as possible
B19: 8 | C19: =IF(ISBLANK(+'Key Business Activities'!C20),"[Business activity]",+'Key Business Activities'!C20) -> [Business activity]
B20: 9 | C20: =IF(ISBLANK(+'Key Business Activities'!C21),"[Business activity]",+'Key Business Activities'!C21) -> [Business activity]
B21: 10 | C21: =IF(ISBLANK(+'Key Business Activities'!C22),"[Business activity]",+'Key Business Activities'!C22) -> [Business activity]

Sheet Dependencies and Recovery Needs
B8: Dependencies and Recovery Needs
B9: [For each key business activity list the dependencies at each time period, starting from the relevant RTO. Then calculate the total requirement across the time periods]
B10: [Note: where cells are automatically populated from other sections of the tool, make sure you expand the cells to show all of their contents.]
B12: Total requirement
B14: REFERENCE: All | C14: BUSINESS ACTIVITY: | D14: All
B15: Dependency | C15: Normal requirement | D15: One hour | E15: Three hours | F15: One day | G15: Three days | H15: One week | I15: One month
B16: People | E16: 2 x website developers | F16: 2 x website developers | G16: Head of Finance 3 in team Human Resources Manager 1 person in team Manufacturing Manager 15 shop-floor staff Customer Services Manager 1 x CS Supervisor 6 CS representatives 2 x website developers | H16: Head of Finance 3 in team Human Resources Manager 1 person in team Manufacturing Manager 15 shop-floor staff Customer Services Manager 1 x CS Supervisor 6 CS representatives 2 x website developers | I16: Head of Sales and Marketing 2 x sales representatives 1 x marketing managers Head of Finance 6 in team Human Resources Manager 3 people in team 1 trainer Manufacturing Manager 30 shop-floor staff Customer Services Manager 2 x CS Supervisor 12 CS representatives Head of Product Development 2 x product managers 2 x website developers
B17: Information and data | E17: Product information Pricing | F17: Product information Pricing | G17: Accounting database Employee records Training records Payroll data Process documentation Product sheets Customer database Appointments information Product information Pricing | H17: Accounting database Employee records Training records Payroll data Process documentation Product sheets Customer database Appointments information Product information Pricing | I17: Customer database Marketing database Accounting database Employee records Training records Payroll data Process documentation Product sheets Customer database Appointments information Product plans Product designs Testing information Product information Pricing
B18: Buildings, work environment and utilities | E18: Hosted with third party | F18: Hosted with third party | G18: 16 desks in HQ building, power and HVAC Manufacturing plant with limited office accommodation, significant power requirements Post room | H18: 16 desks in HQ building, power and HVAC Manufacturing plant with limited office accommodation, significant power requirements Post room | I18: 36 desks in HQ building, power and HVAC Purpose-built manufacturing plant with limited office accommodation, significant power requirements Post room Test area
B19: Facilities, equipment and consumables | E19: 2 desktop computers with access to printer, copier, scanner and fax | F19: 2 desktop computers with access to printer, copier, scanner and fax | G19: 17 desktop computers with access to printer, copier, scanner and fax | H19: 17 desktop computers with access to printer, copier, scanner and fax | I19: 36 desktop computers and 2 laptops with access to printer, copier, scanner and fax
B20: ICT systems | E20: Content management system | F20: Content management system | G20: Finance system Email Internet access HR system Payroll system Manufacturing control system CRM system Website admin Content management system | H20: Finance system Email Internet access HR system Payroll system Manufacturing control system CRM system Website admin Content management system | I20: CRM system Finance system Email Internet access HR system Payroll system eLearning system Manufacturing control system CRM system Website admin Design software Content management system
B21: Transportation | E21: None | F21: None | G21: Commuting from home to work and back | H21: Commuting from home to work and back | I21: Commuting from home to work and back Sales visits by car
B22: Finance | E22: Operational expenses | F22: Operational expenses | G22: Access to company bank account to pay suppliers and employees Operational expenses Petty cash | H22: Access to company bank account to pay suppliers and employees Operational expenses Petty cash | I22: Expenses and payroll Access to company bank account to pay suppliers and employees Operational expenses Petty cash Purchase of test components
B23: Partners and suppliers | E23: Website hosting company | F23: Website hosting company | G23: Cloud accounting system providers Occupational health provider Payroll bureau Main component suppliers Website hosting company | H23: Cloud accounting system providers Occupational health provider Payroll bureau Main component suppliers Website hosting company | I23: Telemarketing bureau Cloud accounting system providers Tax agency Occupational health provider Payroll bureau Wide range of component suppliers Various commodity suppliers Partner with software company Website hosting company
G25: COMPLETED BY: | H25: A. N. Other
G26: DATE: | H26: January 24, 20xx
B27: Requirements per business activity
B29: REFERENCE: [DepRec 1] | C29: BUSINESS ACTIVITY: | D29: =IF(ISBLANK(+'Key Business Activities'!C13),"[Business activity]",+'Key Business Activities'!C13) -> Sales and Marketing
B30: Dependency | C30: Normal requirement | D30: One hour | E30: Three hours | F30: One day | G30: Three days | H30: One week | I30: One month
B31: People | C31: =IF(ISBLANK(+'Key Business Activities'!D13),"[Normal Requirement]",+'Key Business Activities'!D13) -> Head of Sales and Marketing 3 x sales representatives 2 x marketing managers | I31: Head of Sales and Marketing 2 x sales representatives 1 x marketing managers
B32: Information and data | C32: =IF(ISBLANK(+'Key Business Activities'!E13),"[Normal Requirement]",+'Key Business Activities'!E13) -> Customer database Marketing database | I32: Customer database Marketing database
B33: Buildings, work environment and utilities | C33: =IF(ISBLANK(+'Key Business Activities'!F13),"[Normal Requirement]",+'Key Business Activities'!F13) -> 6 desks in HQ building, power and HVAC | I33: 4 desks in HQ building, power and HVAC
B34: Facilities, equipment and consumables | C34: =IF(ISBLANK(+'Key Business Activities'!G13),"[Normal Requirement]",+'Key Business Activities'!G13) -> 3 desktop computers, 3 laptops with access to printer, copier, scanner and fax | I34: 2 desktop computers, 2 laptops with access to printer, copier, scanner and fax
B35: ICT systems | C35: =IF(ISBLANK(+'Key Business Activities'!H13),"[Normal Requirement]",+'Key Business Activities'!H13) -> CRM system Email Internet access | I35: CRM system Email Internet access
B36: Transportation | C36: =IF(ISBLANK(+'Key Business Activities'!I13),"[Normal Requirement]",+'Key Business Activities'!I13) -> Commuting from home to work and back Sales visits by car | I36: Commuting from home to work and back Sales visits by car
B37: Finance | C37: =IF(ISBLANK(+'Key Business Activities'!J13),"[Normal Requirement]",+'Key Business Activities'!J13) -> Expenses and payroll | I37: Expenses and payroll
B38: Partners and suppliers | C38: =IF(ISBLANK(+'Key Business Activities'!K13),"[Normal Requirement]",+'Key Business Activities'!K13) -> Telemarketing bureau | I38: Telemarketing bureau
G40: RTO: | H40: =IF(ISBLANK(+'Key Targets'!E12),"[RTO]",+'Key Targets'!E12) -> 1 month
G41: MBCO: | H41: =IF(ISBLANK(+'Key Targets'!F12),"[MBCO]",+'Key Targets'!F12) -> 50% of normal sales activity
B44: REFERENCE: [DepRec 2] | C44: BUSINESS ACTIVITY: | D44: =IF(ISBLANK(+'Key Business Activities'!C14),"[Business activity]",+'Key Business Activities'!C14) -> Finance
B45: Dependency | C45: Normal requirement | D45: One hour | E45: Three hours | F45: One day | G45: Three days | H45: One week | I45: One month
B46: People | C46: =IF(ISBLANK(+'Key Business Activities'!D14),"[Normal Requirement]",+'Key Business Activities'!D14) -> Head of Finance 6 in team | G46: Head of Finance 3 in team | H46: Head of Finance 3 in team | I46: Head of Finance 6 in team
B47: Information and data | C47: =IF(ISBLANK(+'Key Business Activities'!E14),"[Normal Requirement]",+'Key Business Activities'!E14) -> Accounting database | G47: Accounting database | H47: Accounting database | I47: Accounting database
B48: Buildings, work environment and utilities | C48: =IF(ISBLANK(+'Key Business Activities'!F14),"[Normal Requirement]",+'Key Business Activities'!F14) -> 7 desks in HQ building, power and HVAC | G48: 4 desks in HQ building, power and HVAC | H48: 4 desks in HQ building, power and HVAC | I48: 7 desks in HQ building, power and HVAC
B49: Facilities, equipment and consumables | C49: =IF(ISBLANK(+'Key Business Activities'!G14),"[Normal Requirement]",+'Key Business Activities'!G14) -> 7 desktop computers with access to printer, copier, scanner and fax | G49: 4 desktop computers with access to printer, copier, scanner and fax | H49: 4 desktop computers with access to printer, copier, scanner and fax | I49: 7 desktop computers with access to printer, copier, scanner and fax
B50: ICT systems | C50: =IF(ISBLANK(+'Key Business Activities'!H14),"[Normal Requirement]",+'Key Business Activities'!H14) -> Finance system Email Internet access | G50: Finance system Email Internet access | H50: Finance system Email Internet access | I50: Finance system Email Internet access
B51: Transportation | C51: =IF(ISBLANK(+'Key Business Activities'!I14),"[Normal Requirement]",+'Key Business Activities'!I14) -> Commuting from home to work and back | G51: Commuting from home to work and back | H51: Commuting from home to work and back | I51: Commuting from home to work and back
B52: Finance | C52: =IF(ISBLANK(+'Key Business Activities'!J14),"[Normal Requirement]",+'Key Business Activities'!J14) -> Access to company bank account to pay suppliers and employees | G52: Access to company bank account to pay suppliers and employees | H52: Access to company bank account to pay suppliers and employees | I52: Access to company bank account to pay suppliers and employees
B53: Partners and suppliers | C53: =IF(ISBLANK(+'Key Business Activities'!K14),"[Normal Requirement]",+'Key Business Activities'!K14) -> Cloud accounting system providers Tax agency | G53: Cloud accounting system providers | H53: Cloud accounting system providers | I53: Cloud accounting system providers Tax agency
G55: RTO: | H55: =IF(ISBLANK(+'Key Targets'!E13),"[RTO]",+'Key Targets'!E13) -> 3 days
...

Sheet Priority List
B8: Recovery Priority List
B9: [List the key business activities in order of recovery priority, together with the Recovery Time Objective and Minimum Business Continuity Objectives required]
B11: REF | C11: BUSINESS ACTIVITY | D11: RTO | E11: MBCO REQUIREMENTS AT RTO
B12: 1 | C12: Website sales | D12: 3 hours | E12: Normal service
B13: 2 | C13: Finance | D13: 3 days | E13: Pay suppliers Receive payments
B14: 3 | C14: Human Resources | D14: 3 days | E14: Basic enquiries service
B15: 4 | C15: Manufacturing | D15: 3 days | E15: 50% of normal capacity
B16: 5 | C16: Customer Services | D16: 3 days | E16: Half of normal service level
B17: 6 | C17: Sales and Marketing | D17: 1 month | E17: 50% of normal sales activity
B18: 7 | C18: Product Development | D18: 1 month | E18: Key products only
B19: 8
B20: 9
B21: 10

Sheet Tables
A1: ONE TO FIVE
A2: Select…
A3: 1
A4: 2
A5: 3
A6: 4
A7: 5
