Workbook

Sheet Intro & copyright
B1: ISO/IEC 27001:2022 ISMS Status, Statement of Applicability (SoA) and Controls Status (gap analysis) workbook
B2: Introduction
B3: This spreadsheet is used to record and track the status of your organization as you implement the mandatory and discretionary elements of ISO/IEC 27001.
B4: The main body of ISO/IEC 27001 formally specifies a number of mandatory requirements that must be fulfilled in order for an Information Security Management System to be certified against the standard. All the mandatory requirements for certification concern the management system rather than the information risks and the security controls being managed. For example, the standard requires management to determine the organization's information security risks, assess them, decide how those risks are to be treated, treat them and monitor them, using the policies and procedures defined in the ISMS. The standard does not mandate specific information security controls: the organization does that.
B5: However, Annex A to '27001 outlines a suite of information security controls that the management system would typically manage, provided they are in fact applicable to the organization (which depends on its information security risks). The security controls in Annex A are explained in much more detail in ISO/IEC 27002:2022, and in various other standards, laws, regulations etc.
B6: Instructions
B7: 1. Design and implement an ISMS complying with all the mandatory elements specified in the main body of ISO/IEC 27001, using the drop-down selectors on the status column of the mandatory ISMS requirements sheet to track and record your status against each of the requirements.
B8: 2. Identify and assess the information security risks facing those parts of the organization that are declared in scope for your ISMS, identifying any Annex A controls that are not applicable using the drop-down selectors in the status column of the annex A controls sheet. Note: do not feel constrained by Annex A! Adapt the sheet, modifying the wording and adding-in additional rows if you determine that other security controls are needed to treat your information security risks and obligations (e.g. ISO 22301, privacy laws, PCI-DSS etc.). Annex A is merely a guide, a starting point.
B9: 3. Systematically check and record the status of your security risks and controls, updating the status column of Annex A sheet accordingly.
B10: 4. Once your ISMS is operating normally, the metrics are looking good and you have amassed sufficient evidence ("records"), it can be formally audited for compliance with '27001 by an accredited certification body. They will check that your ISMS fulfills the standard's mandatory requirements, and that your in-scope information security risks are being identified, treated and monitored according to the ISMS policies and procedures. Thereafter, the spreadsheet should both be maintained i.e. updated when the information security risks or controls change, and periodically reviewed/audited.
B11: Document history and acknowledgements
B12: Bala Ramanan donated the original ISO/IEC 27001:2005 version of the 27001 requirements worksheet. Joel Cort added the SoA worksheet. Gary Hinson hacked it about for publication in the ISO27k Toolkit.
... B19: www.ISO27001security.com

Sheet Mandatory ISMS requirements
B1: Status of ISO/IEC 27001 implementation
B2: Section | C2: ISO/IEC 27001 requirement | D2: Status | E2: Notes
B3: 4 | C3: Context of the organisation
B4: 4.1 | C4: Organisational context
B5: 4.1 | C5: Determine the organization's ISMS objectives and any issues that might affect its effectiveness | D5: Optimized
B6: 4.2 | C6: Interested parties
B7: 4.2 (a) | C7: Identify interested parties including applicable laws, regulations, contracts etc. | D7: Optimized
B8: 4.2 (b) | C8: Determine their information security-relevant requirements and obligations | D8: Optimized
B9: 4.3 | C9: ISMS scope
B10: 4.3 | C10: Determine and document the ISMS scope | D10: Optimized
B11: 4.4 | C11: ISMS
B12: 4.4 | C12: Establish, implement, maintain and continually improve an ISMS according to the standard! | D12: Managed
B13: 5 | C13: Leadership
B14: 5.1 | C14: Leadership & commitment
B15: 5.1 | C15: Top management must demonstrate leadership & commitment to the ISMS | D15: Managed
B16: 5.2 | C16: Policy
B17: 5.2 | C17: Establish the information security policy | D17: Optimized
B18: 5.3 | C18: Organizational roles, responsibilities & authorities
B19: 5.3 | C19: Assign and communicate information security rôles & responsibilities | D19: Optimized
B20: 6 | C20: Planning
B21: 6.1 | C21: Actions to address risks & opportunities
B22: 6.1.1 | C22: Design/plan the ISMS to satisfy the requirements, addressing risks & opportunities | D22: Managed
B23: 6.1.2 | C23: Define and apply an information security risk assessment process | D23: Optimized
B24: 6.1.3 | C24: Document and apply an information security risk treatment process | D24: Managed
B25: 6.2 | C25: Information security objectives & plans
B26: 6.2 | C26: Establish and document the information security objectives and plans | D26: Managed
B27: 6.3 | C27: Planning of changes
B28: 6.3 | C28: Substantial changes to the ISMS shall be carried out in a planned manner | D28: Managed | E28: New for 2022
B29: 7 | C29: Support
B30: 7.1 | C30: Resources
B31: 7.1 | C31: Determine and allocate necessary resources for the ISMS | D31: Managed
B32: 7.2 | C32: Competence
B33: 7.2 | C33: Determine, document and make available necessary competences | D33: Optimized
B34: 7.3 | C34: Awareness
B35: 7.3 | C35: Establish a security awareness program | D35: Initial
B36: 7.4 | C36: Communication
B37: 7.4 | C37: Determine the need for internal and external communications relevant to the ISMS | D37: Initial
B38: 7.5 | C38: Documented information
B39: 7.5.1 | C39: Provide documentation required by the standard plus that required by the organization | D39: Initial
B40: 7.5.2 | C40: Provide document titles, authors etc., format them consistently, and review & approve them | D40: Initial
...

Sheet Annex A controls
B1: Statement of Applicability and status of information security controls
B2: Section | C2: Information security control | D2: Status | E2: Description
B3: A5 | C3: Organizational controls
B4: A.5.1 | C4: Policies for information security | D4: Initial
B5: A.5.2 | C5: Information security roles and responsibilities | D5: Initial
B6: A.5.3 | C6: Segregation of duties | D6: Initial
B7: A.5.4 | C7: Management responsibilities | D7: Initial
B8: A.5.5 | C8: Contact with authorities | D8: Initial
B9: A.5.6 | C9: Contact with special interest groups | D9: Initial
B10: A.5.7 | C10: Threat intelligence | D10: Initial
B11: A.5.8 | C11: Information security in project management | D11: Managed
B12: A.5.9 | C12: Inventory of information and other associated assets | D12: Managed
B13: A.5.10 | C13: Acceptable use of information and other associated assets | D13: Managed
B14: A.5.11 | C14: Return of assets | D14: Managed
B15: A.5.12 | C15: Classification of information | D15: Managed
... B40: A.5.37 | C40: Documented operating procedures | D40: Managed
B41: A6 | C41: People controls
B42: A.6.1 | C42: Screening | D42: Managed
B43: A.6.2 | C43: Terms and conditions of employment | D43: Managed
B44: A.6.3 | C44: Information security awareness, education and training | D44: Optimized
B45: A.6.4 | C45: Disciplinary process | D45: Managed
B46: A.6.5 | C46: Responsibilities after termination or change of employment | D46: Managed
B47: A.6.6 | C47: Confidentiality or non-disclosure agreements | D47: Managed
B48: A.6.7 | C48: Remote working | D48: Managed
B49: A.6.8 | C49: Information security event reporting | D49: Managed
B50: A7 | C50: Physical controls
B51: A.7.1 | C51: Physical security perimeters | D51: Managed
B52: A.7.2 | C52: Physical entry | D52: Managed
B53: A.7.3 | C53: Securing offices, rooms and facilities | D53: Managed
B54: A.7.4 | C54: Physical security monitoring | D54: Managed
B55: A.7.5 | C55: Protecting against physical and environmental threats | D55: Managed
B56: A.7.6 | C56: Working in secure areas | D56: Managed
B57: A.7.7 | C57: Clear desk and clear screen | D57: Managed
B58: A.7.8 | C58: Equipment siting and protection | D58: Managed
B59: A.7.9 | C59: Security of assets off-premises | D59: Managed
B60: A.7.10 | C60: Storage media | D60: Managed
B61: A.7.11 | C61: Supporting utilities | D61: Managed
B62: A.7.12 | C62: Cabling security | D62: Managed
... B64: A.7.14 | C64: Secure disposal or re-use of equipment | D64: Managed
B65: A8 | C65: Technological controls
...

Sheet NCA
B1: Statement of Applicability and status of information security controls
B2: Section | C2: Information security control | D2: Status | E2: Description
B3: A5 | C3: Organizational controls
B4: A.5.1 | C4: Policies for information security | D4: Initial
B5: A.5.2 | C5: Information security roles and responsibilities | D5: Initial
B6: A.5.3 | C6: Segregation of duties | D6: Initial
B7: A.5.4 | C7: Management responsibilities | D7: Initial
B8: A.5.5 | C8: Contact with authorities | D8: Initial
B9: A.5.6 | C9: Contact with special interest groups | D9: Initial
B10: A.5.7 | C10: Threat intelligence | D10: Initial
B11: A.5.8 | C11: Information security in project management | D11: Managed
B12: A.5.9 | C12: Inventory of information and other associated assets | D12: Managed
B13: A.5.10 | C13: Acceptable use of information and other associated assets | D13: Managed
B14: A.5.11 | C14: Return of assets | D14: Managed
B15: A.5.12 | C15: Classification of information | D15: Managed
... B40: A.5.37 | C40: Documented operating procedures | D40: Managed
B41: A6 | C41: People controls
B42: A.6.1 | C42: Screening | D42: Managed
B43: A.6.2 | C43: Terms and conditions of employment | D43: Managed
B44: A.6.3 | C44: Information security awareness, education and training | D44: Optimized
B45: A.6.4 | C45: Disciplinary process | D45: Managed
B46: A.6.5 | C46: Responsibilities after termination or change of employment | D46: Managed
B47: A.6.6 | C47: Confidentiality or non-disclosure agreements | D47: Managed
B48: A.6.7 | C48: Remote working | D48: Managed
B49: A.6.8 | C49: Information security event reporting | D49: Managed
B50: A7 | C50: Physical controls
B51: A.7.1 | C51: Physical security perimeters | D51: Managed
B52: A.7.2 | C52: Physical entry | D52: Managed
B53: A.7.3 | C53: Securing offices, rooms and facilities | D53: Managed
B54: A.7.4 | C54: Physical security monitoring | D54: Managed
B55: A.7.5 | C55: Protecting against physical and environmental threats | D55: Managed
B56: A.7.6 | C56: Working in secure areas | D56: Managed
B57: A.7.7 | C57: Clear desk and clear screen | D57: Managed
B58: A.7.8 | C58: Equipment siting and protection | D58: Managed
B59: A.7.9 | C59: Security of assets off-premises | D59: Managed
B60: A.7.10 | C60: Storage media | D60: Managed
B61: A.7.11 | C61: Supporting utilities | D61: Managed
B62: A.7.12 | C62: Cabling security | D62: Managed
... B64: A.7.14 | C64: Secure disposal or re-use of equipment | D64: Managed
B65: A8 | C65: Technological controls
...

Sheet PCI-DSS
B1: Statement of Applicability and status of information security controls
B2: Section | C2: Information security control | D2: Status | E2: Description
B3: A5 | C3: Organizational controls
B4: A.5.1 | C4: Policies for information security | D4: Initial
B5: A.5.2 | C5: Information security roles and responsibilities | D5: Initial
B6: A.5.3 | C6: Segregation of duties | D6: Initial
B7: A.5.4 | C7: Management responsibilities | D7: Initial
B8: A.5.5 | C8: Contact with authorities | D8: Initial
B9: A.5.6 | C9: Contact with special interest groups | D9: Initial
B10: A.5.7 | C10: Threat intelligence | D10: Initial
B11: A.5.8 | C11: Information security in project management | D11: Managed
B12: A.5.9 | C12: Inventory of information and other associated assets | D12: Managed
B13: A.5.10 | C13: Acceptable use of information and other associated assets | D13: Managed
B14: A.5.11 | C14: Return of assets | D14: Managed
B15: A.5.12 | C15: Classification of information | D15: Managed
... B40: A.5.37 | C40: Documented operating procedures | D40: Managed
B41: A6 | C41: People controls
B42: A.6.1 | C42: Screening | D42: Managed
B43: A.6.2 | C43: Terms and conditions of employment | D43: Managed
B44: A.6.3 | C44: Information security awareness, education and training | D44: Optimized
B45: A.6.4 | C45: Disciplinary process | D45: Managed
B46: A.6.5 | C46: Responsibilities after termination or change of employment | D46: Managed
B47: A.6.6 | C47: Confidentiality or non-disclosure agreements | D47: Managed
B48: A.6.7 | C48: Remote working | D48: Managed
B49: A.6.8 | C49: Information security event reporting | D49: Managed
B50: A7 | C50: Physical controls
B51: A.7.1 | C51: Physical security perimeters | D51: Managed
B52: A.7.2 | C52: Physical entry | D52: Managed
B53: A.7.3 | C53: Securing offices, rooms and facilities | D53: Managed
B54: A.7.4 | C54: Physical security monitoring | D54: Managed
B55: A.7.5 | C55: Protecting against physical and environmental threats | D55: Managed
B56: A.7.6 | C56: Working in secure areas | D56: Managed
B57: A.7.7 | C57: Clear desk and clear screen | D57: Managed
B58: A.7.8 | C58: Equipment siting and protection | D58: Managed
B59: A.7.9 | C59: Security of assets off-premises | D59: Managed
B60: A.7.10 | C60: Storage media | D60: Managed
B61: A.7.11 | C61: Supporting utilities | D61: Managed
B62: A.7.12 | C62: Cabling security | D62: Managed
... B64: A.7.14 | C64: Secure disposal or re-use of equipment | D64: Managed
B65: A8 | C65: Technological controls
...

Sheet Metrics
B2: Status | C2: Meaning | D2: Proportion of ISMS requirements | E2: Proportion of information security controls
B3: ? Unknown | C3: Has not even been checked yet | D3: =COUNTIF('Mandatory ISMS requirements'!$D$3:$D$60,$B3)/'Mandatory ISMS requirements'!$D$61 -> 0 | E3: =COUNTIF('Annex A controls'!$D$3:$D$99,$B3)/ControlTotal -> 0
B4: Nonexistent | C4: Complete lack of recognizable policy, procedure, control etc. | D4: =COUNTIF('Mandatory ISMS requirements'!$D$3:$D$60,$B4)/'Mandatory ISMS requirements'!$D$61 -> 0 | E4: =COUNTIF('Annex A controls'!$D$3:$D$99,$B4)/ControlTotal -> 0
B5: Initial | C5: Development has barely started and will require significant work to fulfill the requirements | D5: =COUNTIF('Mandatory ISMS requirements'!$D$3:$D$60,$B5)/'Mandatory ISMS requirements'!$D$61 -> 0.21428571 | E5: =COUNTIF('Annex A controls'!$D$3:$D$99,$B5)/ControlTotal -> 0.075268817
B6: Limited | C6: Progressing nicely but not yet complete | D6: =COUNTIF('Mandatory ISMS requirements'!$D$3:$D$60,$B6)/'Mandatory ISMS requirements'!$D$61 -> 0 | E6: =COUNTIF('Annex A controls'!$D$3:$D$99,$B6)/ControlTotal -> 0
B7: Defined | C7: Development is more or less complete although detail is lacking and/or it is not yet implemented, enforced and actively supported by top management | D7: =COUNTIF('Mandatory ISMS requirements'!$D$3:$D$60,$B7)/'Mandatory ISMS requirements'!$D$61 -> 0 | E7: =COUNTIF('Annex A controls'!$D$3:$D$99,$B7)/ControlTotal -> 0
B8: Managed | C8: Development is complete, the process/control has been implemented and recently started operating | D8: =COUNTIF('Mandatory ISMS requirements'!$D$3:$D$60,$B8)/'Mandatory ISMS requirements'!$D$61 -> 0.42857143 | E8: =COUNTIF('Annex A controls'!$D$3:$D$99,$B8)/ControlTotal -> 0.68817204
B9: Optimized | C9: The requirement is fully satisfied, is operating fully as expected, is being actively monitored and improved, and there is substantial evidence to prove all that to the auditors | D9: =COUNTIF('Mandatory ISMS requirements'!$D$3:$D$60,$B9)/'Mandatory ISMS requirements'!$D$61 -> 0.35714286 | E9: =COUNTIF('Annex A controls'!$D$3:$D$99,$B9)/ControlTotal -> 0.22580645
B10: Not applicable | C10: ALL requirements in the main body of ISO/IEC 27001 are mandatory IF your ISMS is to be certified. Otherwise, managemnent can ignore them. | D10: =COUNTIF('Mandatory ISMS requirements'!$D$3:$D$60,$B10)/'Mandatory ISMS requirements'!$D$61 -> 0 | E10: =COUNTIF('Annex A controls'!$D$3:$D$99,$B10)/ControlTotal -> 0.010752688
C11: Total | D11: =SUM(D3:D10) -> 1 | E11: =SUM(E3:E10) -> 1
