Workbook

Sheet Version
B4: Document | C4: Statement of Applicability
B5: Version | C5: 1
B6: Date | C6: 44957

Sheet Compliance Monitoring Dashboard
C2: ISMS 27001:2022 Dashboard
Z3: Yes
Z4: No
B6: Control Status | C6: Meaning | D6: ISMS Requirements | E6: Annex A Controls
B7: ? Unknown | C7: Has not even been checked yet | D7: =COUNTIF('Mandatory ISMS requirements'!$D$5:$D$57,B7)/'Mandatory ISMS requirements'!$D$58 -> 0 | E7: =COUNTIF('Annex A controls'!$J$5:$J$100,$B7)/93 -> 0
B8: Nonexistent | C8: Complete lack of recognizable policy, procedure, control etc. | D8: =COUNTIF('Mandatory ISMS requirements'!$D$5:$D$57,B8)/'Mandatory ISMS requirements'!$D$58 -> 0 | E8: =COUNTIF('Annex A controls'!$J$5:$J$100,$B8)/93 -> 0
B9: Initial | C9: Development has barely started and will require significant work to fulfill the requirements | D9: =COUNTIF('Mandatory ISMS requirements'!$D$5:$D$57,B9)/'Mandatory ISMS requirements'!$D$58 -> 0 | E9: =COUNTIF('Annex A controls'!$J$5:$J$100,$B9)/93 -> 0
B10: Limited | C10: Progressing nicely but not yet complete | D10: =COUNTIF('Mandatory ISMS requirements'!$D$5:$D$57,B10)/'Mandatory ISMS requirements'!$D$58 -> 0 | E10: =COUNTIF('Annex A controls'!$J$5:$J$100,$B10)/93 -> 0
B11: Defined | C11: Development is more or less complete although detail is lacking and/or it is not yet implemented, enforced and actively supported by top management | D11: =COUNTIF('Mandatory ISMS requirements'!$D$5:$D$57,B11)/'Mandatory ISMS requirements'!$D$58 -> 0 | E11: =COUNTIF('Annex A controls'!$J$5:$J$100,$B11)/93 -> 0
B12: Managed | C12: Development is complete, the process/control has been implemented and recently started operating | D12: =COUNTIF('Mandatory ISMS requirements'!$D$5:$D$57,B12)/'Mandatory ISMS requirements'!$D$58 -> 0.20689655 | E12: =COUNTIF('Annex A controls'!$J$5:$J$100,$B12)/93 -> 1
B13: Optimized | C13: The requirement is fully satisfied, is operating fully as expected, is being actively monitored and improved, and there is substantial evidence to prove all that to the auditors | D13: =COUNTIF('Mandatory ISMS requirements'!$D$5:$D$57,B13)/'Mandatory ISMS requirements'!$D$58 -> 0.79310345 | E13: =COUNTIF('Annex A controls'!$J$5:$J$100,$B13)/93 -> 0
B14: Not applicable | C14: ALL requirements in the main body of ISO/IEC 27001 are mandatory IF your ISMS is to be certified. Otherwise, managemnent can ignore them. | D14: =COUNTIF('Mandatory ISMS requirements'!$D$5:$D$57,B14)/'Mandatory ISMS requirements'!$D$58 -> 0 | E14: =COUNTIF('Annex A controls'!$J$5:$J$100,$B14)/93 -> 0

Sheet Mandatory ISMS requirements
B1: Status of ISO 27001:2022 implementation
B2: Section | C2: ISO/IEC 27001:2022 mandatory requirement | D2: Status | E2: Notes
B3: 4 | C3: Context of the organisation
B4: 4.1 | C4: Organisational context
B5: 4.1 | C5: Understanding the organization and its context | D5: Optimized
B6: 4.2 | C6: Understanding the needs and expectations of interested parties | D6: Optimized
B7: 4.3 | C7: Determining the scope of the information security management system | D7: Optimized
B8: 4.4 | C8: Information security management system | D8: Optimized
B9: 5 | C9: Leadership
B10: 5.1 | C10: Leadership and commitment
B11: 5.1 | C11: Top management must demonstrate leadership & commitment to the ISMS | D11: Optimized
B12: 5.2 | C12: Policy
B13: 5.2 | C13: Document the information security policy | D13: Optimized
B14: 5.3 | C14: Organizational roles, responsibilities and authorities
B15: 5.3 | C15: Assign and communicate information security rôles & responsibilities | D15: Optimized
B16: 6 | C16: Planning
B17: 6.1 | C17: Actions to address risks & opportunities
B18: 6.1.1 | C18: Design/plan the ISMS to satisfy the requirements, addressing risks & opportunities | D18: Optimized
B19: 6.1.2 | C19: Information security risk assessment | D19: Optimized
B20: 6.1.3 | C20: Information security risk treatment | D20: Optimized
B21: 6.2 | C21: Information security objectives and planning to achieve them
B22: 6.2 | C22: Information security objectives and planning to achieve them | D22: Optimized
B23: 7 | C23: Support
B24: 7.1 | C24: Resources
B25: 7.1 | C25: Determine and allocate necessary resources for the ISMS | D25: Optimized
B26: 7.2 | C26: Competence
B27: 7.2 | C27: Determine, document and make available necessary competences | D27: Optimized
B28: 7.3 | C28: Awareness
B29: 7.3 | C29: Establish a security awareness program | D29: Optimized
B30: 7.4 | C30: Communication
B31: 7.4 | C31: Determine the need for internal and external communications relevant to the ISMS | D31: Optimized
B32: 7.5 | C32: Documented information
B33: 7.5.1 | C33: General (Provide documentation required by the standard plus that required by the organization) | D33: Optimized
B34: 7.5.2 | C34: Creating and updating (Provide document titles, authors etc., format them consistently, and review & approve them) | D34: Optimized
B35: 7.5.3 | C35: Control of documented information | D35: Optimized
B36: 8 | C36: Operation
B37: 8.1 | C37: Operational planning and control
B38: 8.1 | C38: Plan, implement, control & document ISMS processes to manage risks (i.e. a risk treatment plan) | D38: Optimized
B39: 8.2 | C39: Information security risk assessment
B40: 8.2 | C40: (Re)assess & document information security risks regularly & on changes | D40: Optimized
...

Sheet Annex A controls
B1: ISO 27001:2022 Statement of Applicability
B2: # | C2: Information security control | D2: Control | E2: Applicable | F2: Reason | J2: Status | K2: Notes
F3: Operational | G3: Regulatory | H3: Legal | I3: Contractual
B4: A5 | C4: Organizational Controls
B5: 5.1 | C5: Policies for information security | D5: Information security policy and topic-specific policies shall be defined, approved by management, published, communicated to and acknowledged by relevant personnel and relevant interested parties, and reviewed at planned intervals and if significant changes occur. | E5: Yes | F5: X | J5: Managed | K5: Information security policies are developed and approved by the CEO. The policies are uploaded on the portal to which all employees have access to.
B6: 5.2 | C6: Information security roles and responsibilities | D6: Information security roles and responsibilities shall be defined and allocated according to the organization needs. | E6: Yes | J6: Managed
B7: 5.3 | C7: Segregation of duties | D7: Conflicting duties and conflicting areas of responsibility shall be segregated. | E7: Yes | J7: Managed
B8: 5.4 | C8: Management responsibilities | D8: Management shall require all personnel to apply information security in accordance with the established information security policy, topic-specific policies and procedures of the organization. | E8: Yes | J8: Managed
B9: 5.5 | C9: Contact with authorities | D9: The organization shall establish and maintain contact with relevant authorities. | E9: Yes | J9: Managed
B10: 5.6 | C10: Contact with special interest groups | D10: The organization shall establish and maintain contact with special interest groups or other specialist security forums and professional associations. | E10: Yes | J10: Managed
B11: 5.7 | C11: Threat intelligence | D11: Information relating to information security threats shall be collected and analysed to produce threat intelligence. | E11: Yes | J11: Managed
B12: 5.8 | C12: Information security in project management | D12: Information security shall be integrated into project management. | E12: Yes | J12: Managed
B13: 5.9 | C13: Inventory of information and other associated assets | D13: An inventory of information and other associated assets, including owners, shall be developed and maintained. | E13: Yes | J13: Managed
B14: 5.10 | C14: Acceptable use of information and other associated assets | D14: Rules for the acceptable use and procedures for handling information and other associated assets shall be identified, documented and implemented. | E14: Yes | J14: Managed
B15: 5.11 | C15: Return of assets | D15: Personnel and other interested parties as appropriate shall return all the organization’s assets in their possession upon change or termination of their employment, contract or agreement. | E15: Yes | J15: Managed
B16: 5.12 | C16: Classification of information | D16: Information shall be classified according to the information security needs of the organization based on confidentiality, integrity, availability and relevant interested party requirements. | E16: Yes | J16: Managed
B17: 5.13 | C17: Labelling of information | D17: An appropriate set of procedures for information labelling shall be developed and implemented in accordance with the information classification scheme adopted by the organization. | E17: Yes | J17: Managed
B18: 5.14 | C18: Information transfer | D18: Information transfer rules, procedures, or agreements shall be in place for all types of transfer facilities within the organization and between the organization and other parties. | E18: Yes | J18: Managed
B19: 5.15 | C19: Access control | D19: Rules to control physical and logical access to information and other associated assets shall be established and implemented based on business and information security requirements. | E19: Yes | J19: Managed
B20: 5.16 | C20: Identity management | D20: The full life cycle of identities shall be managed. | E20: Yes | J20: Managed
B21: 5.17 | C21: Authentication information | D21: Allocation and management of authentication information shall be controlled by a management process, including advising personnel on appropriate handling of authentication information. | E21: Yes | J21: Managed
B22: 5.18 | C22: Access rights | D22: Access rights to information and other associated assets shall be provisioned, reviewed, modified and removed in accordance with the organization’s topic-specific policy on and rules for access control. | E22: Yes | J22: Managed
B23: 5.19 | C23: Information security in supplier relationships | D23: Processes and procedures shall be defined and implemented to manage the information security risks associated with the use of supplier’s products or services. | E23: Yes | J23: Managed
B24: 5.20 | C24: Addressing information security within supplier agreements | D24: Relevant information security requirements shall be established and agreed with each supplier based on the type of supplier relationship. | E24: Yes | J24: Managed
B25: 5.21 | C25: Managing information security in the information and communication technology (ICT) supply chain | D25: Processes and procedures shall be defined and implemented to manage the information security risks associated with the ICT products and services supply chain. | E25: Yes | J25: Managed
B26: 5.22 | C26: Monitoring, review and change management of supplier services | D26: The organization shall regularly monitor, review, evaluate and manage change in supplier information security practices and service delivery. | E26: Yes | J26: Managed
B27: 5.23 | C27: Information security for use of cloud services | D27: Processes for acquisition, use, management and exit from cloud services shall be established in accordance with the organization’s information security requirements. | E27: Yes | J27: Managed
B28: 5.24 | C28: Information security incident management planning and preparation | D28: The organization shall plan and prepare for managing information security incidents by defining, establishing and communicating information security incident management processes, roles and responsibilities. | E28: Yes | J28: Managed
B29: 5.25 | C29: Assessment and decision on information security events | D29: The organization shall assess information security events and decide if they are to be categorized as information security incidents. | E29: Yes | J29: Managed
B30: 5.26 | C30: Response to information security incidents | D30: Information security incidents shall be responded to in accordance with the documented procedures. | E30: Yes | J30: Managed
B31: 5.27 | C31: Learning from information security incidents | D31: Knowledge gained from information security incidents shall be used to strengthen and improve the information security controls. | E31: Yes | J31: Managed
B32: 5.28 | C32: Collection of evidence | D32: The organization shall establish and implement procedures for the identification, collection, acquisition and preservation of evidence related to information security events. | E32: Yes | J32: Managed
B33: 5.29 | C33: Information security during disruption | D33: The organization shall plan how to maintain information security at an appropriate level during disruption. | E33: Yes | J33: Managed
B34: 5.30 | C34: ICT readiness for business continuity | D34: ICT readiness shall be planned, implemented, maintained and tested based on business continuity objectives and ICT continuity requirements. | E34: Yes | J34: Managed
B35: 5.31 | C35: Legal, statutory, regulatory and contractual requirements | D35: Legal, statutory, regulatory and contractual requirements relevant to information security and the organization’s approach to meet these requirements shall be identified, documented and kept up to date. | E35: Yes | J35: Managed
B36: 5.32 | C36: Intellectual property rights | D36: The organization shall implement appropriate procedures to protect intellectual property rights. | E36: Yes | J36: Managed
B37: 5.33 | C37: Protection of records | D37: Records shall be protected from loss, destruction, falsification, unauthorized access and unauthorized release. | E37: Yes | J37: Managed
B38: 5.34 | C38: Privacy and protection of personal identifiable information (PII) | D38: The organization shall identify and meet the requirements regarding the preservation of privacy and protection of PII according to applicable laws and regulations and contractual requirements. | E38: Yes | J38: Managed
B39: 5.35 | C39: Independent review of information security | D39: The organization’s approach to managing information security and its implementation including people, processes and technologies shall be reviewed independently at planned intervals, or when significant changes occur. | E39: Yes | J39: Managed
B40: 5.36 | C40: Compliance with policies, rules and standards for information security | D40: Compliance with the organization’s information security policy, topic-specific policies, rules and standards shall be regularly reviewed. | E40: Yes | J40: Managed
...
